Workbook

Sheet AI Assumptions
A1: AI Acceleration Factors - How Traditional vs AI Days Are Calculated
A2: Yellow cells = user-adjustable inputs | Blue cells = auto-calculated formulas
A4: Section A: AI Acceleration Multipliers by Activity Type
A5: Activity Category | B5: AI Acceleration Factor | C5: Explanation / How AI Reduces Time | D5: Traditional Effort Driver | E5: AI Approach | F5: Residual Manual %
A6: Infrastructure Discovery | B6: 0.3 | C6: 68% savings. AWS Native auto-discovery is mature (agentless + agent-based), covers VMware/Hyper-V/physical well. Lacks unified multi-cloud single-pane — separate scans per platform need manual merging. [Ref: Gartner MQ 2024 + AWS Native product benchmark] | D6: Manual server-by-server inventory, spreadsheet reconciliation, app owner interviews | E6: AWS Native agentless discovery + agent-based deep scan; manual merge needed for multi-cloud consolidated view | F6: 32%
A7: App Dependency Mapping | B7: 0.35 | C7: 62% savings. AWS Native dependency mapping uses network flow + process-level analysis. Good for standard dependencies but limited AI-augmented pattern detection for complex cross-app chains. [Ref: Gartner 2024 - AWS Native rated strong in discovery] | D7: Manual interviews with app owners, network trace analysis, cross-team dependency workshops | E7: AWS Native network flow + process analysis; manual validation still needed for 35-40% of dependencies | F7: 38%
A8: Database Analysis | B8: 0.28 | C8: 65% savings. AWS Native integrates with AWS SCT/Azure DMA for schema analysis. Standard tool integration — no additional AI-assisted fix layer beyond what SCT provides. [Ref: AWS SCT docs + AWS Native integration docs] | D8: Manual schema review, stored proc analysis, compatibility matrix building | E8: AWS Native wraps SCT/DMA scanning; standard compatibility reports without AI-suggested fixes for unconverted objects | F8: 35%
A9: Performance Baseline | B9: 0.25 | C9: 70% savings. AWS Native collects performance metrics via APIs — similar to industry standard. CloudWatch/Azure Monitor integration is well-implemented. [Ref: AWS CloudWatch + AWS Native perf module] | D9: Manual metric collection, spreadsheet charting, baseline documentation, anomaly identification | E9: AWS Native API-driven metric collection + baseline computation; human review for threshold decisions | F9: 30%
A10: Compliance & Security | B10: 0.42 | C10: 50% savings. AWS Native has basic compliance checking but no dedicated compliance microservice. NERC CIP evidence collection is largely manual regardless of tool. [Ref: NERC CIP requirements + AWS Native docs] | D10: Manual control review, evidence collection, policy mapping, regulatory documentation | E10: AWS Native basic compliance rules + gap flagging; manual evidence collection and NERC CIP sign-off | F10: 50%
A11: License Analysis | B11: 0.35 | C11: 58% savings. AWS Native has license tracking module but limited AI-driven BYOL eligibility analysis. Standard CMDB-driven approach. [Ref: Flexera 2024 + AWS Native license module] | D11: Manual license inventory, vendor contract review, BYOL eligibility assessment | E11: AWS Native CMDB-driven license inventory; manual for vendor contract interpretation and BYOL negotiation | F11: 42%
A12: TCO / Cost Modeling | B12: 0.28 | C12: 70% savings. AWS Native has solid TCO modeling with cloud pricing integration. Covers AWS + Azure but requires separate runs per cloud — no single multi-cloud comparison view. [Ref: AWS Pricing + AWS Native cost module] | D12: Manual spreadsheet modeling, vendor quote gathering, assumption documentation | E12: AWS Native auto-generated TCO per cloud platform; manual consolidation for multi-cloud comparison | F12: 30%
A13: Wave Planning | B13: 0.35 | C13: 62% savings. AWS Native wave planning uses dependency data + configurable rules. Functional but rule-based rather than AI-optimized — adequate for most scenarios. [Ref: McKinsey 2023 + AWS Native wave planner] | D13: Manual dependency review, stakeholder negotiation, change window scheduling | E13: AWS Native rule-based wave grouping from dependency data; manual for stakeholder alignment and change windows | F13: 38%
A14: Landing Zone Design | B14: 0.3 | C14: 65% savings (validation only — PG&E provides LZ). AWS Native has LZ templates but limited auto-validation capability. [Ref: AWS Landing Zone Accelerator + AWS Native docs] | D14: Manual architecture review, compliance gap analysis, design documentation | E14: AWS Native template-based LZ design + manual readiness validation; limited automated gap detection | F14: 35%
A15: Terraform/IaC Generation | B15: 0.32 | C15: 70% savings. AWS Native generates Terraform/CloudFormation templates from discovery. Good template library but less dynamic auto-population from live inventory vs purpose-built IaC generators. [Ref: HashiCorp 2024 + AWS Native IaC module] | D15: Manual HCL writing, module development, testing, review iterations | E15: AWS Native Terraform template generation; manual customization still significant for complex modules | F15: 30%
A16: Container Artifact Gen | B16: 0.3 | C16: 55% savings (Industry std: 60%). AWS Native has limited containerization support — basic Dockerfile templates but no AI source-code analysis for runtime dependency detection. Containerization is not AWS Native core strength. [Ref: CNCF 2024 + AWS Native product scope] | D16: Manual Dockerfile creation, K8s manifest writing, Helm chart development | E16: AWS Native basic Dockerfile templates; manual creation still needed for most non-trivial containerization | F16: 45%
A17: Framework Upgrades | B17: 0.35 | C17: 42% savings. AWS Native does not provide framework upgrade assistance — this is outside AWS Native platform scope. Standard developer tooling (IDE + Copilot) applies. [Ref: AWS Native product scope — migration automation, not code modernization] | D17: Manual code refactoring, dependency updates, regression fixing, build testing | E17: No AWS Native capability here; standard IDE + Copilot assist for code changes | F17: 58%
... A31: Vuln Continuous Monitoring | B31: 0.35 | C31: 55% savings. AWS Native does not provide continuous vulnerability monitoring. Requires separate Nessus/Qualys scheduled scans + manual JIRA ticketing. [Ref: Industry avg + AWS Native product scope] | D31: Periodic manual scans, spreadsheet tracking, manual ticket creation, SLA monitoring | E31: No AWS Native continuous vuln monitoring; separate tool integration with manual ticket creation | F31: 45%
A34: Section B: Scale Factors (Server/App Volume Impact on Duration)
A35: Factor | B35: Value | C35: Description
A36: Total Applications | B36: 415 | C36: From PG&E landscape analysis
A37: Total Servers | B37: 4273 | C37: Across all platforms
A38: AWS Apps | B38: 107 | C38: Target platform count
A39: Azure Apps | B39: 145 | C39: Target platform count
A40: Azure Local Apps | B40: 110 | C40: Target platform count
A41: HyperV Apps | B41: 20 | C41: Target platform count
A42: Containerize Apps | B42: 159 | C42: Journey type count
A43: Lift-and-Shift Apps | B43: 179 | C43: Journey type count
A44: Retire Apps | B44: 24 | C44: Journey type count
A45: Base Days per Discovery (per 100 servers) | B45: 5 | C45: Industry benchmark: 5 days per 100 servers manual
A46: Base Days per App (Dependency Map) | B46: 0.3 | C46: Industry benchmark: ~0.3 days per app manual
A47: Base Days per App (Wave Planning) | B47: 0.2 | C47: Industry benchmark: ~0.2 days per app manual
... A49: Base Days per App (Containerize) | B49: 1.2 | C49: Industry benchmark: ~1.2 days per app manual
A52: Section C: How Duration Is Calculated (Formula Methodology)
A53: TRADITIONAL DAYS = Base Days per unit x Volume (apps or servers) x Complexity multiplier
A54: Example: Infrastructure Discovery = (4273 servers / 100) x 5 base days = ~214 person-days, split across 3 clouds
A55: Example: App Dependency Mapping = 415 apps x 0.3 days/app = ~125 person-days, split across 3 clouds
A57: AI-ACCELERATED DAYS = Traditional Days x AI Acceleration Factor (from Section A)
A58: Example: Discovery Traditional=20 days (AWS share), AI Factor=20% => AI Days = 20 x 0.20 = 4 days
A59: Example: Containerize Trad=25 days, AI Factor=20% => AI Days = 25 x 0.20 = 5 days
A61: TIME SAVED % = (Traditional - AI) / Traditional x 100
...

Sheet Migration Activities
A1: PG&E Cloud Migration - Activities, Duration & AI Accelerator Savings
A2: 415 Apps | 4,273 Servers | All durations formula-driven from AI Assumptions tab (yellow = input, blue = formula)
A3: CIS CLD (AWS/Azure) | CIS EIT (Azure Local/HyperV) | ADM (Containerize/Framework) | IQE (Testing) | CyberSec (Security)
A5: Phase | B5: Activity | C5: Team | D5: Description | E5: AWS Trad (Days) | F5: AWS AI (Days) | G5: AWS Saved % | H5: Azure Trad (Days) | I5: Azure AI (Days) | J5: Azure Saved % | K5: AzLocal/HV Trad (Days) | L5: AzLocal/HV AI (Days) | M5: AzLocal/HV Saved % | N5: AWS Transform+Kiro Accelerator Activity | O5: AI Factor Ref | P5: How Calculated
A6: Phase 1: Discovery & Assessment [COMPLETED]
B7: Infrastructure Discovery (4273 servers) [DONE] | C7: CIS CLD + EIT | D7: COMPLETED - Scan all VMs, physical, DBs, network | E7: 0 | F7: 0 | G7: =IF(E7>0,(E7-F7)/E7*100,0) | H7: 0 | I7: 0 | J7: =IF(H7>0,(H7-I7)/H7*100,0) | K7: 0 | L7: 0 | M7: =IF(K7>0,(K7-L7)/K7*100,0) | N7: AWS Native Discovery: Agentless + agent-based scan, VMware/Hyper-V/physical inventory | O7: Infrastructure Discovery | P7: 4273 svrs / 100 x 5d = 214 total, split by platform
B8: App Dependency Mapping (415 apps) [DONE] | C8: CIS CLD + ADM | D8: COMPLETED - Map inter-app dependencies, all 415 apps | E8: 0 | F8: 0 | G8: =IF(E8>0,(E8-F8)/E8*100,0) | H8: 0 | I8: 0 | J8: =IF(H8>0,(H8-I8)/H8*100,0) | K8: 0 | L8: 0 | M8: =IF(K8>0,(K8-L8)/K8*100,0) | N8: AWS Native Dependency: Network flow + process analysis; manual validation for 35-40% of deps | O8: App Dependency Mapping | P8: 415 apps x 0.3d = 125 total, split by platform
B9: Database Schema Analysis [DONE] | C9: CIS CLD | D9: COMPLETED - Analyze schemas, stored procs, compatibility | E9: 0 | F9: 0 | G9: =IF(E9>0,(E9-F9)/E9*100,0) | H9: 0 | I9: 0 | J9: =IF(H9>0,(H9-I9)/H9*100,0) | K9: 0 | L9: 0 | M9: =IF(K9>0,(K9-L9)/K9*100,0) | N9: AWS Native DB Module: Wraps AWS SCT/Azure DMA for schema analysis; standard reports | O9: Database Analysis | P9: DB-heavy apps analyzed per platform
B10: Performance Baseline [DONE] | C10: CIS CLD + EIT | D10: COMPLETED - Capture CPU, mem, IOPS baselines per server | E10: 0 | F10: 0 | G10: =IF(E10>0,(E10-F10)/E10*100,0) | H10: 0 | I10: 0 | J10: =IF(H10>0,(H10-I10)/H10*100,0) | K10: 0 | L10: 0 | M10: =IF(K10>0,(K10-L10)/K10*100,0) | N10: AWS Native Perf: API-driven metric collection via CloudWatch/Azure Monitor | O10: Performance Baseline | P10: 4273 servers, automated metric collection
B11: Compliance & Security Audit [DONE] | C11: CyberSec | D11: COMPLETED - PG&E compliance (NERC CIP), security gaps | E11: 0 | F11: 0 | G11: =IF(E11>0,(E11-F11)/E11*100,0) | H11: 0 | I11: 0 | J11: =IF(H11>0,(H11-I11)/H11*100,0) | K11: 0 | L11: 0 | M11: =IF(K11>0,(K11-L11)/K11*100,0) | N11: AWS Native Compliance: Basic rule checking + gap flagging; no dedicated compliance service | O11: Compliance & Security | P11: Regulated utility - higher residual manual
B12: License Analysis (BYOL) [DONE] | C12: CIS CLD | D12: COMPLETED - Audit Oracle, SQL Server, SAP for BYOL | E12: 0 | F12: 0 | G12: =IF(E12>0,(E12-F12)/E12*100,0) | H12: 0 | I12: 0 | J12: =IF(H12>0,(H12-I12)/H12*100,0) | K12: 0 | L12: 0 | M12: =IF(K12>0,(K12-L12)/K12*100,0) | N12: AWS Native License: CMDB-driven inventory; manual BYOL analysis required | O12: License Analysis | P12: CMDB-driven license correlation
B13: TCO / Cost Modeling [DONE] | C13: CIS CLD | D13: COMPLETED - Build TCO for each target platform | E13: 0 | F13: 0 | G13: =IF(E13>0,(E13-F13)/E13*100,0) | H13: 0 | I13: 0 | J13: =IF(H13>0,(H13-I13)/H13*100,0) | K13: 0 | L13: 0 | M13: =IF(K13>0,(K13-L13)/K13*100,0) | N13: AWS Native Cost: TCO per cloud; manual consolidation for multi-cloud comparison | O13: TCO / Cost Modeling | P13: Auto-generated from discovery data
B14: Journey Assignment & 6R [DONE] | C14: CIS CLD + ADM | D14: COMPLETED - Classify 415 apps into journeys | E14: 0 | F14: 0 | G14: =IF(E14>0,(E14-F14)/E14*100,0) | H14: 0 | I14: 0 | J14: =IF(H14>0,(H14-I14)/H14*100,0) | K14: 0 | L14: 0 | M14: =IF(K14>0,(K14-L14)/K14*100,0) | N14: AWS Native Rules: Rule-based 6R classification; less AI-augmented than purpose-built platforms | O14: Wave Planning | P14: AI classifies based on app profile
B15: Vulnerability Baseline Scan (4273 servers) [DONE] | C15: CyberSec | D15: COMPLETED - Full vuln scan of all source servers pre-migration, CVSS categorization | E15: 0 | F15: 0 | G15: =IF(E15>0,(E15-F15)/E15*100,0) | H15: 0 | I15: 0 | J15: =IF(H15>0,(H15-I15)/H15*100,0) | K15: 0 | L15: 0 | M15: =IF(K15>0,(K15-L15)/K15*100,0) | N15: Not AWS Native scope: Separate Nessus/Qualys with manual CVSS triage | O15: Vuln Discovery Scan | P15: 4273 servers, CVSS-prioritized report
B16: Vuln Remediation Plan (Pre-Migration) [DONE] | C16: CyberSec | D16: COMPLETED - Prioritize critical/high CVEs for remediation before migration | E16: 0 | F16: 0 | G16: =IF(E16>0,(E16-F16)/E16*100,0) | H16: 0 | I16: 0 | J16: =IF(H16>0,(H16-I16)/H16*100,0) | K16: 0 | L16: 0 | M16: =IF(K16>0,(K16-L16)/K16*100,0) | N16: Not AWS Native scope: Separate ServiceNow for remediation planning | O16: Vuln Remediation Planning | P16: Fix critical CVEs before migrating workloads
A17: Phase 2: Planning & Design
B18: Wave Planning (7 waves) | C18: CIS CLD | D18: Group 415 apps into 7 waves | E18: 12 | F18: =ROUND(E18*'AI Assumptions'!B13,0) | G18: =IF(E18>0,(E18-F18)/E18*100,0) | H18: 12 | I18: =ROUND(H18*'AI Assumptions'!B13,0) | J18: =IF(H18>0,(H18-I18)/H18*100,0) | K18: 12 | L18: =ROUND(K18*'AI Assumptions'!B13,0) | M18: =IF(K18>0,(K18-L18)/K18*100,0) | N18: AWS Native Wave: Rule-based wave grouping from dependency data; configurable rules engine | O18: Wave Planning | P18: 415 apps x 0.2d = 83 total, graph optimization
B19: LZ Validation - AWS (PG&E Provided) | C19: CIS CLD | D19: Validate PG&E-built VPC/subnets/SG/IAM | E19: 3 | F19: =ROUND(E19*'AI Assumptions'!B14,0) | G19: =IF(E19>0,(E19-F19)/E19*100,0) | H19: 0 | I19: 0 | J19: =IF(H19>0,(H19-I19)/H19*100,0) | K19: 0 | L19: 0 | M19: =IF(K19>0,(K19-L19)/K19*100,0) | N19: AWS Native LZ: Template-based design; limited automated validation | O19: Landing Zone Design | P19: PG&E provides LZ; Infosys validates readiness
B20: LZ Validation - Azure (PG&E Provided) | C20: CIS CLD | D20: Validate PG&E-built VNet/NSG/RBAC | E20: 0 | F20: 0 | G20: =IF(E20>0,(E20-F20)/E20*100,0) | H20: 3 | I20: =ROUND(H20*'AI Assumptions'!B14,0) | J20: =IF(H20>0,(H20-I20)/H20*100,0) | K20: 0 | L20: 0 | M20: =IF(K20>0,(K20-L20)/K20*100,0) | N20: AWS Native LZ: Template-based design; limited automated validation | O20: Landing Zone Design | P20: PG&E provides LZ; Infosys validates readiness
B21: LZ Validation - AzLocal/HV (PG&E Provided) | C21: CIS EIT | D21: Validate PG&E-built Azure Local/HyperV | E21: 0 | F21: 0 | G21: =IF(E21>0,(E21-F21)/E21*100,0) | H21: 0 | I21: 0 | J21: =IF(H21>0,(H21-I21)/H21*100,0) | K21: 5 | L21: =ROUND(K21*'AI Assumptions'!B14,0) | M21: =IF(K21>0,(K21-L21)/K21*100,0) | N21: AWS Native LZ: Basic cluster template; manual capacity validation | O21: Landing Zone Design | P21: PG&E provides infra; EIT validates config
B22: App-Level IaC Generation | C22: CIS CLD + EIT | D22: Generate app-level Terraform (SG, LB, DNS) | E22: 10 | F22: =ROUND(E22*'AI Assumptions'!B15,0) | G22: =IF(E22>0,(E22-F22)/E22*100,0) | H22: 10 | I22: =ROUND(H22*'AI Assumptions'!B15,0) | J22: =IF(H22>0,(H22-I22)/H22*100,0) | K22: 12 | L22: =ROUND(K22*'AI Assumptions'!B15,0) | M22: =IF(K22>0,(K22-L22)/K22*100,0) | N22: AWS Native IaC: Terraform template generation; manual customization still significant | O22: Terraform/IaC Generation | P22: App-level only; foundational IaC by PG&E
B23: DB Migration Planning (DMS/DMA) | C23: CIS CLD | D23: Schema conversion, CDC strategy | E23: 10 | F23: =ROUND(E23*'AI Assumptions'!B8,0) | G23: =IF(E23>0,(E23-F23)/E23*100,0) | H23: 10 | I23: =ROUND(H23*'AI Assumptions'!B8,0) | J23: =IF(H23>0,(H23-I23)/H23*100,0) | K23: 12 | L23: =ROUND(K23*'AI Assumptions'!B8,0) | M23: =IF(K23>0,(K23-L23)/K23*100,0) | N23: AWS Native DB: DMS task design wrapping SCT; manual CDC strategy | O23: Database Analysis | P23: DMS task planning per DB target
B24: Containerization Architecture | C24: ADM | D24: Docker/K8s design for 159 apps | E24: 15 | F24: =ROUND(E24*'AI Assumptions'!B16,0) | G24: =IF(E24>0,(E24-F24)/E24*100,0) | H24: 15 | I24: =ROUND(H24*'AI Assumptions'!B16,0) | J24: =IF(H24>0,(H24-I24)/H24*100,0) | K24: 15 | L24: =ROUND(K24*'AI Assumptions'!B16,0) | M24: =IF(K24>0,(K24-L24)/K24*100,0) | N24: AWS Native: Limited containerization — basic Dockerfile templates, no AI source analysis | O24: Container Artifact Gen | P24: 159 containerize apps, arch design
B25: Rollback & DR Strategy | C25: CIS CLD | D25: Rollback procedures per wave, DR plan | E25: 8 | F25: =ROUND(E25*'AI Assumptions'!B10,0) | G25: =IF(E25>0,(E25-F25)/E25*100,0) | H25: 8 | I25: =ROUND(H25*'AI Assumptions'!B10,0) | J25: =IF(H25>0,(H25-I25)/H25*100,0) | K25: 8 | L25: =ROUND(K25*'AI Assumptions'!B10,0) | M25: =IF(K25>0,(K25-L25)/K25*100,0) | N25: AWS Native Rollback: Workflow-based rollback; manual DR checklist | O25: Compliance & Security | P25: Template-based + manual review
B26: Business Impact Assessment | C26: CIS CLD | D26: Downtime cost per app tier | E26: 5 | F26: =ROUND(E26*'AI Assumptions'!B12,0) | G26: =IF(E26>0,(E26-F26)/E26*100,0) | H26: 5 | I26: =ROUND(H26*'AI Assumptions'!B12,0) | J26: =IF(H26>0,(H26-I26)/H26*100,0) | K26: 5 | L26: =ROUND(K26*'AI Assumptions'!B12,0) | M26: =IF(K26>0,(K26-L26)/K26*100,0) | N26: AWS Native Cost: Basic downtime estimate; manual impact assessment | O26: TCO / Cost Modeling | P26: AI computes from app metadata
A27: Phase 3: Build & Prepare
B28: App-Level Provisioning - AWS | C28: CIS CLD | D28: Deploy app SGs, target groups, DNS in PG&E LZ | E28: 5 | F28: =ROUND(E28*'AI Assumptions'!B15,0) | G28: =IF(E28>0,(E28-F28)/E28*100,0) | H28: 0 | I28: 0 | J28: =IF(H28>0,(H28-I28)/H28*100,0) | K28: 0 | L28: 0 | M28: =IF(K28>0,(K28-L28)/K28*100,0) | N28: AWS Native Executor: Terraform apply orchestration; manual for complex configs | O28: Terraform/IaC Generation | P28: PG&E LZ ready; app-level config only
B29: App-Level Provisioning - Azure | C29: CIS CLD | D29: Deploy app NSGs, LB rules, DNS in PG&E LZ | E29: 0 | F29: 0 | G29: =IF(E29>0,(E29-F29)/E29*100,0) | H29: 5 | I29: =ROUND(H29*'AI Assumptions'!B15,0) | J29: =IF(H29>0,(H29-I29)/H29*100,0) | K29: 0 | L29: 0 | M29: =IF(K29>0,(K29-L29)/K29*100,0) | N29: AWS Native Executor: Terraform apply orchestration; manual for complex configs | O29: Terraform/IaC Generation | P29: PG&E LZ ready; app-level config only
B30: Workload Onboarding - AzLocal/HV | C30: CIS EIT | D30: Onboard workloads to PG&E-built clusters | E30: 0 | F30: 0 | G30: =IF(E30>0,(E30-F30)/E30*100,0) | H30: 0 | I30: 0 | J30: =IF(H30>0,(H30-I30)/H30*100,0) | K30: 10 | L30: =ROUND(K30*'AI Assumptions'!B18,0) | M30: =IF(K30>0,(K30-L30)/K30*100,0) | N30: AWS Native Executor: Basic migration orchestration; manual placement optimization | O30: Middleware Migration | P30: PG&E provides infra; EIT onboards apps
B31: Container Artifact Gen (159 apps) | C31: ADM | D31: Dockerfiles, K8s manifests, Helm charts | E31: 25 | F31: =ROUND(E31*'AI Assumptions'!B16,0) | G31: =IF(E31>0,(E31-F31)/E31*100,0) | H31: 25 | I31: =ROUND(H31*'AI Assumptions'!B16,0) | J31: =IF(H31>0,(H31-I31)/H31*100,0) | K31: 25 | L31: =ROUND(K31*'AI Assumptions'!B16,0) | M31: =IF(K31>0,(K31-L31)/K31*100,0) | N31: AWS Native: Basic Dockerfile templates; no AI source-code analysis | O31: Container Artifact Gen | P31: 159 apps x AI source analysis
B32: Framework Upgrades (.Net/Java) | C32: ADM | D32: .Net/Java upgrades for containerization | E32: 20 | F32: =ROUND(E32*'AI Assumptions'!B17,0) | G32: =IF(E32>0,(E32-F32)/E32*100,0) | H32: 20 | I32: =ROUND(H32*'AI Assumptions'!B17,0) | J32: =IF(H32>0,(H32-I32)/H32*100,0) | K32: 20 | L32: =ROUND(K32*'AI Assumptions'!B17,0) | M32: =IF(K32>0,(K32-L32)/K32*100,0) | N32: Not AWS Native scope: IDE + Copilot for code modernization | O32: Framework Upgrades | P32: Semi-auto, 40% residual manual
B33: Middleware Upgrades & Jobs | C33: ADM | D33: Middleware versions, batch job migration | E33: 15 | F33: =ROUND(E33*'AI Assumptions'!B18,0) | G33: =IF(E33>0,(E33-F33)/E33*100,0) | H33: 15 | I33: =ROUND(H33*'AI Assumptions'!B18,0) | J33: =IF(H33>0,(H33-I33)/H33*100,0) | K33: 15 | L33: =ROUND(K33*'AI Assumptions'!B18,0) | M33: =IF(K33>0,(K33-L33)/K33*100,0) | N33: AWS Native: Basic config export; manual for custom plugins and job scheduling | O33: Middleware Migration | P33: Config extraction + manual verification
B34: DB Schema Conversion | C34: CIS CLD | D34: Convert stored procs, triggers, functions | E34: 20 | F34: =ROUND(E34*'AI Assumptions'!B19,0) | G34: =IF(E34>0,(E34-F34)/E34*100,0) | H34: 20 | I34: =ROUND(H34*'AI Assumptions'!B19,0) | J34: =IF(H34>0,(H34-I34)/H34*100,0) | K34: 22 | L34: =ROUND(K34*'AI Assumptions'!B19,0) | M34: =IF(K34>0,(K34-L34)/K34*100,0) | N34: AWS Native DB: SCT auto-conversion only; no AI-assisted fix layer | O34: Schema Conversion | P34: SCT auto-converts 80%, AI fixes rest
B35: Migration Rehearsal (Dry Run) | C35: CIS CLD + ADM | D35: Full rehearsal per wave in non-prod | E35: 15 | F35: =ROUND(E35*'AI Assumptions'!B20,0) | G35: =IF(E35>0,(E35-F35)/E35*100,0) | H35: 15 | I35: =ROUND(H35*'AI Assumptions'!B20,0) | J35: =IF(H35>0,(H35-I35)/H35*100,0) | K35: 18 | L35: =ROUND(K35*'AI Assumptions'!B20,0) | M35: =IF(K35>0,(K35-L35)/K35*100,0) | N35: AWS Native Workflow: Orchestrated rehearsal; manual outcome validation via checklist | O35: Rehearsal / Dry Run | P35: AI orchestrates + validates outcomes
B36: Integration Testing | C36: IQE | D36: Validate connectivity, APIs, data integrity | E36: 15 | F36: =ROUND(E36*'AI Assumptions'!B25,0) | G36: =IF(E36>0,(E36-F36)/E36*100,0) | H36: 15 | I36: =ROUND(H36*'AI Assumptions'!B25,0) | J36: =IF(H36>0,(H36-I36)/H36*100,0) | K36: 18 | L36: =ROUND(K36*'AI Assumptions'!B25,0) | M36: =IF(K36>0,(K36-L36)/K36*100,0) | N36: Not AWS Native scope: Manual integration testing with standard frameworks | O36: NFR Testing (30%) | P36: IQE functional validation post-rehearsal
B37: Security Validation | C37: CyberSec | D37: Vulnerability scans, compliance per wave | E37: 8 | F37: =ROUND(E37*'AI Assumptions'!B10,0) | G37: =IF(E37>0,(E37-F37)/E37*100,0) | H37: 8 | I37: =ROUND(H37*'AI Assumptions'!B10,0) | J37: =IF(H37>0,(H37-I37)/H37*100,0) | K37: 10 | L37: =ROUND(K37*'AI Assumptions'!B10,0) | M37: =IF(K37>0,(K37-L37)/K37*100,0) | N37: AWS Native: Basic compliance check; manual security validation | O37: Compliance & Security | P37: PG&E NERC CIP requirements
B38: Pre-Migration Patch Execution | C38: CyberSec | D38: Patch critical/high CVEs on source before cutover | E38: 12 | F38: =ROUND(E38*'AI Assumptions'!B30,0) | G38: =IF(E38>0,(E38-F38)/E38*100,0) | H38: 12 | I38: =ROUND(H38*'AI Assumptions'!B30,0) | J38: =IF(H38>0,(H38-I38)/H38*100,0) | K38: 15 | L38: =ROUND(K38*'AI Assumptions'!B30,0) | M38: =IF(K38>0,(K38-L38)/K38*100,0) | N38: Not AWS Native scope: Separate SSM/Ansible; manual NERC CIP evidence | O38: Vuln Patch Execution | P38: Must-fix before migration per PG&E policy
A39: Phase 4: Migration Execution
B40: Wave 1: Pilot (10-15 apps) | C40: CIS CLD | D40: Pilot batch across all platforms | E40: 8 | F40: =ROUND(E40*'AI Assumptions'!B21,0) | G40: =IF(E40>0,(E40-F40)/E40*100,0) | H40: 8 | I40: =ROUND(H40*'AI Assumptions'!B21,0) | J40: =IF(H40>0,(H40-I40)/H40*100,0) | K40: 10 | L40: =ROUND(K40*'AI Assumptions'!B21,0) | M40: =IF(K40>0,(K40-L40)/K40*100,0) | N40: AWS Native Execution: Workflow-based pilot; good orchestration, manual validation | O40: Rehost Execution | P40: Validate patterns before scale
B41: Rehost / Lift-and-Shift (179 apps) | C41: CIS CLD + EIT | D41: V->V, P->V, HyperVisor-Replace | E41: 40 | F41: =ROUND(E41*'AI Assumptions'!B21,0) | G41: =IF(E41>0,(E41-F41)/E41*100,0) | H41: 45 | I41: =ROUND(H41*'AI Assumptions'!B21,0) | J41: =IF(H41>0,(H41-I41)/H41*100,0) | K41: 50 | L41: =ROUND(K41*'AI Assumptions'!B21,0) | M41: =IF(K41>0,(K41-L41)/K41*100,0) | N41: AWS Native Rehost: Strong MGN/ASR orchestration + cutover — AWS Native core strength | O41: Rehost Execution | P41: 179 apps x 0.5d = ~90 total, split by platform
...

Sheet Cost Estimation
A1: PG&E Migration Cost - 4-Team Model, 2-Year Projection
A2: 415 Apps | 4,273 Servers | Yellow = adjustable input | All costs formula-driven
A4: Section A: Team Role Rate Card
A5: Team | B5: Role | C5: Hourly ($) | D5: Daily ($) (8 hrs) | E5: Monthly ($) (22 days) | F5: FTE Count | G5: Monthly Cost ($) | H5: Annual Cost ($) | I5: Location
A6: CIS CLD | B6: Cloud Migration Lead | C6: 180 | D6: =C6*8 | E6: =D6*22 | F6: 1 | G6: =E6*F6 | H6: =G6*12 | I6: Onshore
A7: CIS CLD | B7: Sr. Migration Engineer | C7: 150 | D7: =C7*8 | E7: =D7*22 | F7: 4 | G7: =E7*F7 | H7: =G7*12 | I7: Offshore
A8: CIS CLD | B8: Migration Engineer | C8: 100 | D8: =C8*8 | E8: =D8*22 | F8: 6 | G8: =E8*F8 | H8: =G8*12 | I8: Offshore
A9: CIS CLD | B9: DB Migration Specialist | C9: 160 | D9: =C9*8 | E9: =D9*22 | F9: 2 | G9: =E9*F9 | H9: =G9*12 | I9: Offshore
A10: CIS CLD | B10: DevOps / SRE Engineer | C10: 140 | D10: =C10*8 | E10: =D10*22 | F10: 2 | G10: =E10*F10 | H10: =G10*12 | I10: Offshore
A11: CIS CLD | B11: Network Engineer (App-Level) | C11: 125 | D11: =C11*8 | E11: =D11*22 | F11: 0 | G11: =E11*F11 | H11: =G11*12 | I11: Offshore
A12: CIS CLD | B12: Project Manager | C12: 155 | D12: =C12*8 | E12: =D12*22 | F12: 1 | G12: =E12*F12 | H12: =G12*12 | I12: Onshore
A13: CIS EIT | B13: Azure Local / HyperV Lead | C13: 170 | D13: =C13*8 | E13: =D13*22 | F13: 1 | G13: =E13*F13 | H13: =G13*12 | I13: Onshore
A14: CIS EIT | B14: Infrastructure Engineer | C14: 130 | D14: =C14*8 | E14: =D14*22 | F14: 3 | G14: =E14*F14 | H14: =G14*12 | I14: Offshore
A15: CIS EIT | B15: Network Engineer (App-Level) | C15: 125 | D15: =C15*8 | E15: =D15*22 | F15: 0 | G15: =E15*F15 | H15: =G15*12 | I15: Offshore
A16: ADM | B16: App Modernization Lead | C16: 175 | D16: =C16*8 | E16: =D16*22 | F16: 1 | G16: =E16*F16 | H16: =G16*12 | I16: Onshore
A17: ADM | B17: Sr. App Developer | C17: 145 | D17: =C17*8 | E17: =D17*22 | F17: 4 | G17: =E17*F17 | H17: =G17*12 | I17: Offshore
... A28: FinOps | B28: FinOps Analyst | C28: 130 | D28: =C28*8 | E28: =D28*22 | F28: 1 | G28: =E28*F28 | H28: =G28*12 | I28: Offshore
A29: TOTAL ALL TEAMS | F29: =SUM(F6:F28) | G29: =SUM(G6:G28) | H29: =SUM(H6:H28)
A32: Section B: Phase-Based Cost (Duration from Migration Activities tab)
A33: Phase | B33: Primary Team | C33: Trad Days | D33: AI Days | E33: Team FTEs | F33: Blended Daily Rate ($) | G33: Traditional Cost ($) | H33: AI Cost ($) | I33: Savings ($) | J33: Savings % | K33: Cloud Infra $/Month | L33: Phase Total AI ($)
A34: Discovery & Assessment [COMPLETED] | B34: CIS CLD + EIT | C34: 0 | D34: 0 | E34: 0 | F34: 1050 | G34: =C34*E34*F34 | H34: =D34*E34*F34 | I34: =G34-H34 | J34: =IF(G34>0,(G34-H34)/G34*100,0) | K34: 0 | L34: =H34+(K34*ROUND(D34/22,1))+2000
A35: Planning & Design | B35: CIS CLD + ADM | C35: 68 | D35: 23 | E35: 14 | F35: 1100 | G35: =C35*E35*F35 | H35: =D35*E35*F35 | I35: =G35-H35 | J35: =IF(G35>0,(G35-H35)/G35*100,0) | K35: 500 | L35: =H35+(K35*ROUND(D35/22,1))+2000
A36: Build & Prepare | B36: All Teams | C36: 108 | D36: 37 | E36: 18 | F36: 1050 | G36: =C36*E36*F36 | H36: =D36*E36*F36 | I36: =G36-H36 | J36: =IF(G36>0,(G36-H36)/G36*100,0) | K36: 1000 | L36: =H36+(K36*ROUND(D36/22,1))+2000
A37: Migration Execution - Rehost | B37: CIS CLD + EIT | C37: 83 | D37: 28 | E37: 14 | F37: 1050 | G37: =C37*E37*F37 | H37: =D37*E37*F37 | I37: =G37-H37 | J37: =IF(G37>0,(G37-H37)/G37*100,0) | K37: 0 | L37: =H37+(K37*ROUND(D37/22,1))+2000
A38: Migration Execution - Containerize | B38: ADM | C38: 43 | D38: 15 | E38: 15 | F38: 1000 | G38: =C38*E38*F38 | H38: =D38*E38*F38 | I38: =G38-H38 | J38: =IF(G38>0,(G38-H38)/G38*100,0) | K38: 0 | L38: =H38+(K38*ROUND(D38/22,1))+2000
A39: Migration Execution - Other | B39: CIS CLD | C39: 30 | D39: 10 | E39: 8 | F39: 1100 | G39: =C39*E39*F39 | H39: =D39*E39*F39 | I39: =G39-H39 | J39: =IF(G39>0,(G39-H39)/G39*100,0) | K39: 0 | L39: =H39+(K39*ROUND(D39/22,1))+2000
A40: Testing - FR (Rearchitect 60%) | B40: IQE | C40: 53 | D40: 18 | E40: 9 | F40: 1000 | G40: =C40*E40*F40 | H40: =D40*E40*F40 | I40: =G40-H40 | J40: =IF(G40>0,(G40-H40)/G40*100,0) | K40: 0 | L40: =H40+(K40*ROUND(D40/22,1))+2000
A41: Testing - NFR (Replatform 30%) | B41: IQE | C41: 32 | D41: 11 | E41: 6 | F41: 1050 | G41: =C41*E41*F41 | H41: =D41*E41*F41 | I41: =G41-H41 | J41: =IF(G41>0,(G41-H41)/G41*100,0) | K41: 0 | L41: =H41+(K41*ROUND(D41/22,1))+2000
A42: Testing - Security & UAT | B42: IQE + CyberSec | C42: 20 | D42: 7 | E42: 5 | F42: 1100 | G42: =C42*E42*F42 | H42: =D42*E42*F42 | I42: =G42-H42 | J42: =IF(G42>0,(G42-H42)/G42*100,0) | K42: 0 | L42: =H42+(K42*ROUND(D42/22,1))+2000
A43: Vulnerability Management (All Phases) | B43: CyberSec | C43: 68 | D43: 23 | E43: 4 | F43: 1100 | G43: =C43*E43*F43 | H43: =D43*E43*F43 | I43: =G43-H43 | J43: =IF(G43>0,(G43-H43)/G43*100,0) | K43: 0 | L43: =H43+(K43*ROUND(D43/22,1))+2000
A44: Post-Migration Optimize | B44: CIS CLD | C44: 48 | D44: 16 | E44: 8 | F44: 1050 | G44: =C44*E44*F44 | H44: =D44*E44*F44 | I44: =G44-H44 | J44: =IF(G44>0,(G44-H44)/G44*100,0) | K44: 0 | L44: =H44+(K44*ROUND(D44/22,1))+2000
A45: TOTAL ALL PHASES | C45: =SUM(C34:C44) | D45: =SUM(D34:D44) | G45: =SUM(G34:G44) | H45: =SUM(H34:H44) | I45: =SUM(I34:I44) | J45: =IF(G45>0,(G45-H45)/G45*100,0) | K45: =SUM(K34:K44) | L45: =SUM(L34:L44)
A48: Section C: 2-Year Cost Projection
A49: Cost Category | B49: Year 1 ($) | C49: Year 2 ($) | D49: 2-Year Total ($) | E49: Notes
A50: Migration Labor (AI Accelerated) | B50: =H45 | C50: =H45*0.15 | D50: =B50+C50 | E50: Year 2 = 15% steady-state
A51: Cloud Infrastructure (App-Level Only) | B51: =K45*12 | C51: =K45*12*0.85 | D51: =B51+C51 | E51: PG&E bears LZ/network; app-level only
A52: AI Platform License | B52: 48000 | C52: 48000 | D52: =B52+C52 | E52: AWS Transform+Kiro enterprise
A53: Tooling & 3rd Party | B53: 25000 | C53: 18000 | D53: =B53+C53 | E53: DMS, Terraform Cloud, etc.
A54: Training & Enablement | B54: 20000 | C54: 8000 | D54: =B54+C54 | E54: All 4 teams
A55: CyberSec & Compliance | B55: 35000 | C55: 25000 | D55: =B55+C55 | E55: NERC CIP ongoing
...

Sheet Executive Summary
A1: PG&E Migration - Executive Summary
A3: Metric | B3: Value
A4: Total Applications | B4: 415
A5: Total Servers | B5: 4273
A6: Traditional Duration - AWS (Days) | B6: ='Migration Activities'!E66
A7: AI-Accelerated Duration - AWS (Days) | B7: ='Migration Activities'!F66
A8: Time Saved % - AWS | B8: ='Migration Activities'!G66
A9: Traditional Migration Cost ($) | B9: ='Cost Estimation'!G45
A10: AI-Accelerated Cost ($) | B10: ='Cost Estimation'!L45
A11: 2-Year Grand Total ($) | B11: ='Cost Estimation'!D58
A12: Net Savings vs Traditional ($) | B12: ='Cost Estimation'!B61
A13: Total FTEs | B13: ='Cost Estimation'!F29
A16: Key: AI Days = Traditional Days x AI Factor (from AI Assumptions tab)
A17: Change any yellow cell to model different scenarios. All formulas auto-update.

Sheet Executive Dashboard
A1: PG&E Cloud Migration — Executive Dashboard
A2: 415 Applications | 4,273 Servers | 5 Teams | AI-Accelerated with AWS Transform+Kiro
A4: Duration Comparison (Days) | Q4: KEY METRICS
A5: Platform | B5: Traditional | C5: AI-Accelerated | D5: Days Saved | Q5: Applications | R5: 415
A6: AWS (107 apps) | B6: ='Migration Activities'!E66 | C6: ='Migration Activities'!F66 | D6: =B6-C6 | Q6: Servers | R6: 4,273
A7: Azure (145 apps) | B7: ='Migration Activities'!H66 | C7: ='Migration Activities'!I66 | D7: =B7-C7 | Q7: Target Platforms | R7: AWS + Azure + AzLocal
A8: Azure Local/HV (130 apps) | B8: ='Migration Activities'!K66 | C8: ='Migration Activities'!L66 | D8: =B8-C8 | Q8: Teams | R8: CIS CLD + EIT + ADM + IQE
Q10: Time Saved (AWS) | R10: ='Migration Activities'!G66
A11: Cost Comparison ($) | Q11: Cost Savings ($) | R11: ='Cost Estimation'!B61
A12: Category | B12: Amount ($) | Q12: 2-Year Investment | R12: ='Cost Estimation'!D58
A13: Traditional Migration (2yr) | B13: ='Cost Estimation'!B60 | Q13: Total FTEs | R13: ='Cost Estimation'!F29
A14: AI-Accelerated (2yr Grand Total) | B14: ='Cost Estimation'!D58
A15: Net Savings | B15: ='Cost Estimation'!B61 | Q15: PG&E Provides | R15: LZ + Network + Infra
Q16: Infosys Delivers | R16: Migration + Modernization
Q17: AI Accelerator | R17: AWS Transform+Kiro
A18: Phase Effort Breakdown (AI Days)
A19: Phase | B19: AI Days
A20: Discovery | B20: ='Cost Estimation'!D34
A21: Planning | B21: ='Cost Estimation'!D35
A22: Build | B22: ='Cost Estimation'!D36
A23: Rehost Exec | B23: ='Cost Estimation'!D37
A24: Containerize Exec | B24: ='Cost Estimation'!D38
A25: Other Exec | B25: ='Cost Estimation'!D39
A26: FR Testing | B26: ='Cost Estimation'!D40
A27: NFR Testing | B27: ='Cost Estimation'!D41
A28: Security/UAT | B28: ='Cost Estimation'!D42
A29: Vuln Mgmt | B29: ='Cost Estimation'!D43
A30: Optimize | B30: ='Cost Estimation'!D44
A34: Team FTE Allocation
A35: Team | B35: FTEs
A36: CIS CLD (Rehost/Replatform) | B36: 17
A37: CIS EIT (Azure Local/HyperV) | B37: 5
A38: ADM (Containerize/Framework) | B38: 15
A39: IQE (Testing) | B39: 9
A40: CyberSec (Security/VulnMgmt) | B40: 4
A41: FinOps | B41: 1
A52: App Distribution by Journey | C52: Servers by Platform
A53: Journey | B53: Apps | C53: Platform | D53: Servers
A54: Lift-and-Shift | B54: 179 | C54: AWS | D54: 719
A55: Containerize | B55: 159 | C55: Azure | D55: 852
...

Sheet Team Revenue View
A1: PG&E Migration — Team-wise FTE, Cost & Revenue Breakdown
A2: All values formula-driven from Cost Estimation tab | Yellow = adjustable inputs | Margin % adjustable per team
A4: Section A: Team FTE & Monthly/Annual Cost (from Cost Estimation Rate Card)
A5: Team | B5: Roles | C5: Total FTEs | D5: Avg Hourly Rate ($) | E5: Monthly Cost ($) | F5: Annual Cost ($) | G5: Scope / Responsibility
A6: CIS CLD | B6: Cloud Migration Lead, Sr. Migration Engineers (4), Migration Engineers (6), DB Specialist (2), DevOps (2), PM | C6: =SUM('Cost Estimation'!F6:'Cost Estimation'!F12) | D6: =IF(C6>0,SUMPRODUCT('Cost Estimation'!C6:C12*'Cost Estimation'!F6:F12)/C6,0) | E6: =SUM('Cost Estimation'!G6:'Cost Estimation'!G12) | F6: =SUM('Cost Estimation'!H6:'Cost Estimation'!H12) | G6: Rehost, Replatform, DB Migration, Wave Planning on AWS & Azure
A7: CIS EIT | B7: Azure Local/HyperV Lead, Infrastructure Engineers (3) | C7: =SUM('Cost Estimation'!F13:'Cost Estimation'!F15) | D7: =IF(C7>0,SUMPRODUCT('Cost Estimation'!C13:C15*'Cost Estimation'!F13:F15)/C7,0) | E7: =SUM('Cost Estimation'!G13:'Cost Estimation'!G15) | F7: =SUM('Cost Estimation'!H13:'Cost Estimation'!H15) | G7: Azure Local & HyperV workload onboarding, cluster validation
A8: ADM | B8: App Modernization Lead, Sr. Developers (4), Developers (6), Middleware (2), DevOps K8s (2) | C8: =SUM('Cost Estimation'!F16:'Cost Estimation'!F20) | D8: =IF(C8>0,SUMPRODUCT('Cost Estimation'!C16:C20*'Cost Estimation'!F16:F20)/C8,0) | E8: =SUM('Cost Estimation'!G16:'Cost Estimation'!G20) | F8: =SUM('Cost Estimation'!H16:'Cost Estimation'!H20) | G8: Containerization (159 apps), .Net/Java upgrades, Middleware migration
A9: IQE | B9: Test Lead, SR Test Engineers FR (3), Perf NFR (2), Security (1), Automation (2) | C9: =SUM('Cost Estimation'!F21:'Cost Estimation'!F25) | D9: =IF(C9>0,SUMPRODUCT('Cost Estimation'!C21:C25*'Cost Estimation'!F21:F25)/C9,0) | E9: =SUM('Cost Estimation'!G21:'Cost Estimation'!G25) | F9: =SUM('Cost Estimation'!H21:'Cost Estimation'!H25) | G9: FR Testing 60%, NFR Testing 30%, Security Testing, UAT coordination
A10: CyberSec (Vuln Mgmt) | B10: Security Analyst, Vuln Mgmt Engineers (2) | C10: =SUM('Cost Estimation'!F26:'Cost Estimation'!F27) | D10: =IF(C10>0,SUMPRODUCT('Cost Estimation'!C26:C27*'Cost Estimation'!F26:F27)/C10,0) | E10: =SUM('Cost Estimation'!G26:'Cost Estimation'!G27) | F10: =SUM('Cost Estimation'!H26:'Cost Estimation'!H27) | G10: Vulnerability scanning, remediation, patching, compliance, NERC CIP
A11: FinOps | B11: FinOps Analyst | C11: ='Cost Estimation'!F28 | D11: ='Cost Estimation'!C28 | E11: ='Cost Estimation'!G28 | F11: ='Cost Estimation'!H28 | G11: Cost optimization, RI/SP recommendations
A12: TOTAL | C12: =SUM(C6:C11) | E12: =SUM(E6:E11) | F12: =SUM(F6:F11)
A15: Section B: Team-wise 2-Year Revenue Model (Margin-Adjustable)
A16: Team | B16: FTEs | C16: Year 1 Duration (Mo) | D16: Year 1 Cost ($) | E16: Year 2 Duration (Mo) | F16: Year 2 Cost ($) | G16: 2-Year Total Cost ($) | H16: Margin % (Adjust) | I16: Year 1 Revenue ($) | J16: Year 2 Revenue ($) | K16: 2-Year Revenue ($) | L16: % of Total Revenue
A17: CIS CLD | B17: =C6 | C17: 12 | D17: =E6*C17 | E17: 3 | F17: =E6*E17 | G17: =D17+F17 | H17: 0.25 | I17: =D17/(1-H17) | J17: =F17/(1-H17) | K17: =I17+J17 | L17: =IF(K23>0,K17/K23,0)
A18: CIS EIT | B18: =C7 | C18: 10 | D18: =E7*C18 | E18: 2 | F18: =E7*E18 | G18: =D18+F18 | H18: 0.25 | I18: =D18/(1-H18) | J18: =F18/(1-H18) | K18: =I18+J18 | L18: =IF(K23>0,K18/K23,0)
A19: ADM | B19: =C8 | C19: 12 | D19: =E8*C19 | E19: 3 | F19: =E8*E19 | G19: =D19+F19 | H19: 0.25 | I19: =D19/(1-H19) | J19: =F19/(1-H19) | K19: =I19+J19 | L19: =IF(K23>0,K19/K23,0)
A20: IQE | B20: =C9 | C20: 10 | D20: =E9*C20 | E20: 2 | F20: =E9*E20 | G20: =D20+F20 | H20: 0.22 | I20: =D20/(1-H20) | J20: =F20/(1-H20) | K20: =I20+J20 | L20: =IF(K23>0,K20/K23,0)
A21: CyberSec (Vuln Mgmt) | B21: =C10 | C21: 12 | D21: =E10*C21 | E21: 6 | F21: =E10*E21 | G21: =D21+F21 | H21: 0.28 | I21: =D21/(1-H21) | J21: =F21/(1-H21) | K21: =I21+J21 | L21: =IF(K23>0,K21/K23,0)
A22: FinOps | B22: =C11 | C22: 8 | D22: =E11*C22 | E22: 4 | F22: =E11*E22 | G22: =D22+F22 | H22: 0.2 | I22: =D22/(1-H22) | J22: =F22/(1-H22) | K22: =I22+J22 | L22: =IF(K23>0,K22/K23,0)
A23: TOTAL | B23: =SUM(B17:B22) | D23: =SUM(D17:D22) | F23: =SUM(F17:F22) | G23: =SUM(G17:G22) | I23: =SUM(I17:I22) | J23: =SUM(J17:J22) | K23: =SUM(K17:K22) | L23: 1
A26: Section C: Key Revenue Metrics
A27: Total 2-Year Cost (All Teams) | B27: =G23
A28: Total 2-Year Revenue (All Teams) | B28: =K23
A29: Total Gross Margin ($) | B29: =K23-G23
A30: Blended Margin % | B30: =IF(K23>0,(K23-G23)/K23,0)
A32: Largest Team by Revenue | B32: CIS CLD
A33: Largest Team by FTEs | B33: =C6
A34: CyberSec/Vuln Mgmt Revenue Share | B34: =K21/K23
A35: Total FTEs Deployed | B35: =B23
A36: Avg Revenue per FTE (2yr) | B36: =IF(B23>0,K23/B23,0)

Sheet Tool vs Industry Benchmark
A1: AWS Transform+Kiro vs Industry Standard — Honest Benchmark Comparison
A2: Industry = Generic tooling (AWS Migration Hub + separate SCT + separate Terraform + manual glue) | AWS Native = Integrated AI platform
A4: Category | B4: Industry Std Savings % | C4: AWS Native Savings % | D4: Delta (Improvement) | E4: Industry Standard Approach (Generic Tools) | F4: AWS Transform+Kiro Advantage (What Our Tool Adds) | G4: Why The Delta (Honest Assessment) | H4: Risk if Overclaimed | I4: Confidence Level | J4: Industry Reference
A5: Infrastructure Discovery | B5: 0.65 | C5: 0.72 | D5: =C5-B5 | E5: AWS Migration Hub + Azure Migrate run separately; results in 2 spreadsheets that need manual merging for multi-cloud view | F5: Single-pane discovery across AWS+Azure+AzLocal with unified topology map, 29 component types auto-detected, cross-cloud dependency view | G5: +7%: Unified multi-cloud view eliminates manual merge of separate tool outputs. For 4273 servers across 3 clouds, this saves 2-3 days of reconciliation per discovery cycle | H5: Over-claim if PG&E has heavily air-gapped systems that no tool can reach | I5: High | J5: Gartner 2024 + internal benchmark
A6: App Dependency Mapping | B6: 0.6 | C6: 0.65 | D6: =C6-B6 | E6: ServiceNow CMDB + Dynatrace/AppDynamics for runtime deps; still misses 30-40% of dependencies requiring manual app-owner interviews | F6: Network flow tracing + CMDB correlation + AI-powered graph building in one workflow; reduces manual interview rounds from 3 to 1 | G6: +5%: AI graph building catches cross-app patterns that individual tools miss. Conservative delta — dependency mapping is inherently hard regardless of tooling | H6: Dependency mapping accuracy is never 100%; app owner validation always needed | I6: Medium | J6: Gartner 2024
A7: Database Analysis | B7: 0.65 | C7: 0.7 | D7: =C7-B7 | E7: AWS SCT + Azure DMA run separately; conversion reports need manual cross-referencing; no AI-assisted fix suggestions | F7: DB Remediation Engine runs SCT + provides AI-assisted fix suggestions for unconverted objects; cross-cloud DB compatibility matrix in one view | G7: +5%: AI-assisted fix suggestions for unconverted stored procs reduce manual effort. SCT still does the heavy lifting — our tool adds the remediation layer | H7: Complex PL/SQL (PG&E Oracle legacy) may still need DBA manual rewrite regardless | I7: Medium-High | J7: AWS SCT docs
A8: TCO / Cost Modeling | B8: 0.7 | C8: 0.75 | D8: =C8-B8 | E8: AWS Pricing Calculator + Azure TCO Calculator run separately; manual Excel consolidation for multi-cloud comparison | F8: MCP cloud-cost service generates unified multi-cloud TCO from discovery data with live pricing APIs; auto-comparison across AWS/Azure/AzLocal | G8: +5%: Eliminates manual multi-cloud spreadsheet merging. Auto-links TCO to actual discovered inventory rather than manual input estimates | H8: EDP/RI negotiation and business assumptions still need stakeholder input regardless | I8: High | J8: AWS Pricing + Cobalt
A9: Performance Baseline | B9: 0.7 | C9: 0.7 | D9: =C9-B9 | E9: CloudWatch + Azure Monitor + custom scripts; metric collection well-automated by cloud-native tools | F9: Aggregates metrics across all 3 clouds in unified baseline dashboard; but cloud-native tools already do this well individually | G9: 0%: No significant delta. Cloud-native monitoring tools are mature. Our value is unified view, not faster collection | H9: Honest: cloud-native tools are already excellent here | I9: High | J9: AWS CloudWatch
A10: Compliance & Security (NERC CIP) | B10: 0.5 | C10: 0.52 | D10: =C10-B10 | E10: Separate compliance scanning tools (Prisma, Prowler) + manual NERC CIP evidence collection; heavily regulated = heavily manual | F10: MCP compliance-framework service + guardrails engine scan against frameworks; but NERC CIP evidence collection and regulatory sign-off remain manual regardless | G10: +2%: Marginal improvement. Compliance for regulated utilities is fundamentally manual-intensive. Our scanning is faster but the bottleneck is human review and regulatory evidence | H10: DO NOT overclaim here. NERC CIP compliance is 70%+ manual — no tool changes this | I10: Low | J10: NERC CIP reqs
A11: Wave Planning | B11: 0.6 | C11: 0.65 | D11: =C11-B11 | E11: Manual wave grouping using dependency data from discovery; spreadsheet-based optimization; stakeholder negotiation is the bottleneck | F11: Graph-based wave optimizer uses dependency data + risk scoring + parallel simulation; generates optimal wave plan that would take weeks manually | G11: +5%: Algorithm-optimized wave grouping is genuinely faster than manual spreadsheet analysis. But stakeholder alignment (50% of wave planning effort) is unchanged | H11: Stakeholder negotiation window constraints cannot be automated | I11: Medium-High | J11: McKinsey 2023
A12: Terraform/IaC Generation | B12: 0.7 | C12: 0.75 | D12: =C12-B12 | E12: Manual HCL writing using Terraform docs + module registry; separate tool from discovery — no auto-population from discovered inventory | F12: MCP terraform-generator auto-generates HCL from discovery data; app-level resources (SGs, LBs, DNS) pre-populated with actual values from inventory | G12: +5%: Auto-population from discovery data eliminates the manual step of translating inventory into Terraform variables. Module customization and PR review still manual | H12: Complex modules (custom VPC peering, Transit Gateway) still need manual HCL | I12: High | J12: HashiCorp 2024
A13: Container Artifact Gen | B13: 0.6 | C13: 0.65 | D13: =C13-B13 | E13: Manual Dockerfile writing + K8s manifest creation; tools like Kompose help but dont analyze source code | F13: AI source-code analysis generates Dockerfiles + K8s manifests + Helm charts tailored to actual app stack; identifies runtime dependencies automatically | G13: +5%: Source code analysis catches dependencies that manual Dockerfile writing misses. But custom configs, multi-stage builds, sidecar patterns still need manual tuning | H13: Non-standard stacks (legacy .NET Framework 4.x, COBOL wrappers) need manual Dockerfiles | I13: Medium | J13: CNCF 2024
A14: Framework Upgrades | B14: 0.45 | C14: 0.47 | D14: =C14-B14 | E14: Manual code refactoring with IDE assistance; GitHub Copilot helps but doesnt understand migration context | F14: Upgrade Advisor identifies breaking changes + dependency conflicts in migration context; but actual code changes are still manual developer work | G14: +2%: Marginal. Code refactoring is fundamentally a developer task. Our tool helps with identification, not execution. Honest: AI assist is ~30-50% for code changes (GitHub Copilot data) | H14: DO NOT overclaim. Framework upgrades = developer skill, not tool capability | I14: Low | J14: GitHub Copilot
A15: Middleware Migration | B15: 0.45 | C15: 0.47 | D15: =C15-B15 | E15: Manual config extraction + version migration; custom plugins need per-plugin analysis | F15: Config extraction automation + partial middleware mapping; but version differences and custom plugins still need manual migration | G15: +2%: Marginal. Similar to framework upgrades — tool helps with config extraction but the hard part (plugin compat, job scheduling) is manual | H15: Middleware migration complexity varies wildly by product (WebLogic vs Tomcat vs IIS) | I15: Low | J15: Industry avg
A16: Schema Conversion | B16: 0.6 | C16: 0.65 | D16: =C16-B16 | E16: AWS SCT auto-converts 60-80% of simple objects; complex PL/SQL needs manual DBA rewrite; no AI-assisted suggestions | F16: DB Remediation Engine wraps SCT + adds AI-suggested fixes for unconverted objects; pattern matching for common PL/SQL-to-PostgreSQL transforms | G16: +5%: AI pattern matching handles common conversion patterns that SCT marks as "manual action needed". Saves DBA time on repetitive patterns, but complex custom PL/SQL still needs expert | H16: PG&E Oracle databases with 10+ years of PL/SQL — complexity may exceed AI pattern library | I16: Medium | J16: AWS SCT tiers
... A28: Vuln Continuous Monitoring | B28: 0.6 | C28: 0.62 | D28: =C28-B28 | E28: Scheduled scans + manual ticket creation in JIRA/ServiceNow; periodic reporting | F28: Continuous scanning + auto-ticketing + Grafana vuln posture dashboard with SLA tracking | G28: +2%: Auto-ticketing and dashboard are convenient but not transformational. The real work is remediation follow-up which is manual regardless | H28: Dashboard ≠ remediation. Pretty charts dont fix CVEs | I28: Medium | J28: Industry avg
A29: WEIGHTED AVERAGE | B29: =AVERAGE(B5:B28) | C29: =AVERAGE(C5:C28) | D29: =C29-B29 | G29: AWS Transform+Kiro provides ~3-4% incremental improvement over industry standard on average
A32: Honest Summary: Where AWS Transform+Kiro Genuinely Adds Value
A33: STRONG ADVANTAGES (+5-7% over industry): Integration & Multi-Cloud Unification
A34: 1. UNIFIED MULTI-CLOUD DISCOVERY: Single scan across AWS+Azure+AzLocal vs running 3 separate tools and merging spreadsheets. For 4273 servers across 3 clouds, this saves 3-5 days of reconciliation.
A35: 2. DISCOVERY-TO-IaC PIPELINE: Terraform auto-generated FROM discovery data — no manual translation of inventory into HCL variables. Industry tools have a gap between discovery output and IaC input.
A36: 3. DISCOVERY-TO-TCO PIPELINE: TCO auto-generated from actual inventory vs manual AWS/Azure pricing calculator input. Eliminates data-entry errors and multi-cloud comparison spreadsheets.
A37: 4. DB REMEDIATION LAYER: Goes beyond SCT reporting — provides AI-suggested fixes for unconverted objects. SCT tells you what failed; our tool suggests how to fix it.
A38: 5. MIGRATION-CONTEXT VULN TRIAGE: Generic vuln scanners dont know migration context. Our tool deprioritizes CVEs on servers being retired, prioritizes servers being migrated first.
A40: MODERATE ADVANTAGES (+2-3%): Orchestration & Workflow Automation
A41: 6. ORCHESTRATED EXECUTION: Single pipeline for replication -> cutover -> DNS -> validation vs manual handoffs between MGN console, Route53, and monitoring dashboard.
A42: 7. REHEARSAL ORCHESTRATION: Automated rehearsal execution + outcome validation vs manual runbook + spreadsheet checklist.
A43: 8. AI TEST GENERATION: Test cases auto-generated from app behavior analysis. Saves ~20-30% of test design time. Execution speed is same (Selenium/Cypress).
A44: 9. PRE-BUILT MONITORING: Templates auto-deployed from discovery metadata. Saves dashboard creation time but custom PG&E SLOs still manual.
... A61: Industry Standard Blended Savings: =B29 | AWS Native Blended Savings: =C29 | Net Improvement: =D29

Sheet Cost by Cloud
A1: PG&E Migration Cost by Cloud Platform — AWS Transform+Kiro
A2: 415 Apps | 4,273 Servers | Discovery COMPLETED | PG&E provides LZ/Networking
A4: Section A: Migration Duration by Cloud
A5: Cloud Platform | B5: Apps | C5: Servers | D5: Traditional Days | E5: AI Factor | F5: AI Days | G5: Days Saved | H5: Savings % | I5: Months Saved
A6: AWS | B6: 107 | C6: 719 | D6: 533 | E6: 0.34 | F6: =D6*E6 | G6: =D6-F6 | H6: =IF(D6>0,(D6-F6)/D6,0) | I6: =ROUND(G6/22,1)
A7: Azure | B7: 145 | C7: 852 | D7: 538 | E7: 0.5 | F7: =D7*E7 | G7: =D7-F7 | H7: =IF(D7>0,(D7-F7)/D7,0) | I7: =ROUND(G7/22,1)
A8: Azure Local / HyperV | B8: 130 | C8: 2702 | D8: 586 | E8: 0.52 | F8: =D8*E8 | G8: =D8-F8 | H8: =IF(D8>0,(D8-F8)/D8,0) | I8: =ROUND(G8/22,1)
A9: TOTAL | B9: =SUM(B6:B8) | C9: =SUM(C6:C8) | D9: =SUM(D6:D8) | F9: =SUM(F6:F8) | G9: =SUM(G6:G8) | H9: =IF(D9>0,(D9-F9)/D9,0) | I9: =ROUND(G9/22,1)
A12: Section B: Migration Cost by Cloud (2-Year)
A13: Cloud Platform | B13: AI Days | C13: Avg FTEs | D13: Blended Rate ($) | E13: Y1 Labor ($) | F13: Y2 Labor (13% SS) | G13: Platform License ($) | H13: Tooling & Other ($) | I13: 2-Year Total ($)
A14: AWS (107 apps) | B14: 181 | C14: 5 | D14: 1050 | E14: =B14*C14*D14 | F14: =E14*0.13 | G14: 0 | H14: 40000 | I14: =E14+F14+G14+H14
A15: Azure (145 apps) | B15: 269 | C15: 6 | D15: 1050 | E15: =B15*C15*D15 | F15: =E15*0.13 | G15: 0 | H15: 40000 | I15: =E15+F15+G15+H15
A16: Azure Local/HV (130 apps) | B16: 305 | C16: 6 | D16: 1050 | E16: =B16*C16*D16 | F16: =E16*0.13 | G16: 0 | H16: 40000 | I16: =E16+F16+G16+H16
A17: Contingency (12%) | I17: =SUM(I14:I16)*0.12
A18: GRAND TOTAL (2-Year) | E18: =SUM(E14:E16) | F18: =SUM(F14:F16) | I18: =SUM(I14:I16)+I17
A20: Traditional 2-Year (No AI) | I20: 12349312
A21: NET SAVINGS | I21: =I20-I18
A23: Tool: AWS Transform+Kiro
A24: AWS-native: best for AWS. Azure/AzLocal use industry-std tools (50-52%)
A25: CAVEAT: Yellow rows = Azure/AzLocal use industry-standard tools (50-52% savings), NOT AWS-native tools
